Workbook

Sheet Vollzelle - 10µm(Cr2032) - For
B2: Prälithiierte Vollzellen (10µm) die den Vollfaktoriellen Versuchsplan des Prälithiierungsgrades in Abhängigkeit der Prälithiierungsdauer untersuchen
B5: Prälithiiert - 10µm - 1h Stunde
B6: Atmosphäre während der Prälithiierung: | C6: O2: <2 ppm | D6: H2O: <2 ppm
C8: Atmosphäre während der Assemblierung: | G8: O2: <1,0 ppm | H8: O2: <1,0 ppm
B10: df_MH_MA_VZ_3,8_10µm_1h_5 | D10: 1. Anode: | E10: 0.0249 | F10: g | G10: 1. Kathode: | H10: 0.0376 | I10: g | J10: berechnete/theoretische Zellkapazität: | K10: =(H10*1000-'Material - Abmessungen'!E25)*'Material - Abmessungen'!E20*0.96 -> 5.5705471 | L10: mAh | M10: Kapazität nach der Formierung: | N10: 5.1619 | O10: mAh | P10: N:P-Verhältnis: | Q10: =(((E10*1000)-'Material - Abmessungen'!E17-('Material - Abmessungen'!E49*1000))*'Material - Abmessungen'!E10*0.697)/K10 -> 3.2831646 | R10: Lithiierung der Anode: | S10: =Q10^(-1) -> 0.30458418
B11: df_MH_MA_VZ_3,8_10µm_1h_6 | D11: 2. Anode: | E11: 0.0249 | F11: g | G11: 2. Kathode: | H11: 0.0368 | I11: g | J11: berechnete/theoretische Zellkapazität: | K11: =(H11*1000-'Material - Abmessungen'!E25)*'Material - Abmessungen'!E20*0.96 -> 5.4284671 | L11: mAh | M11: Kapazität nach der Formierung: | N11: 4.9853 | O11: mAh | P11: N:P-Verhältnis: | Q11: =((E11*1000-'Material - Abmessungen'!E17-('Material - Abmessungen'!E49*1000))*'Material - Abmessungen'!E10*0.697)/K11 -> 3.3690953 | R11: Lithiierung der Anode: | S11: =Q11^(-1) -> 0.29681559
B12: df_MH_MA_VZ_3,8_10µm_1h_9 | D12: 3. Anode: | E12: 0.0252 | F12: g | G12: 3. Kathode: | H12: 0.0374 | I12: g | J12: berechnete/theoretische Zellkapazität: | K12: =(H12*1000-'Material - Abmessungen'!E25)*'Material - Abmessungen'!E20*0.96 -> 5.5350271 | L12: mAh | M12: Kapazität nach der Formierung: | N12: 5.1486 | O12: mAh | P12: N:P-Verhältnis: | Q12: =((E12*1000-'Material - Abmessungen'!E17-('Material - Abmessungen'!E49*1000))*'Material - Abmessungen'!E10*0.697)/K12 -> 3.4394397 | R12: Lithiierung der Anode: | S12: =Q12^(-1) -> 0.29074503
B13: df_MH_MA_VZ_3,8_10µm_1h_10 | D13: 4.Anode: | E13: 0.0252 | F13: g | G13: 4. Kathode: | H13: 0.0374 | I13: g | J13: berechnete/theoretische Zellkapazität: | K13: =(H13*1000-'Material - Abmessungen'!E25)*'Material - Abmessungen'!E20*0.96 -> 5.5350271 | L13: mAh | M13: Kapazität nach der Formierung: | N13: 5.1427 | O13: mAh | P13: N:P-Verhältnis: | Q13: =((E13*1000-'Material - Abmessungen'!E17-('Material - Abmessungen'!E49*1000))*'Material - Abmessungen'!E10*0.697)/K13 -> 3.4394397 | R13: Lithiierung der Anode: | S13: =Q13^(-1) -> 0.29074503
B14: df_MH_MA_VZ_3,8_10µm_1h_11 | D14: 5.Anode: | E14: 0.0252 | F14: g | G14: 5.Kathode: | H14: 0.037 | I14: g | J14: berechnete/theoretische Zellkapazität: | K14: =(H14*1000-'Material - Abmessungen'!E25)*'Material - Abmessungen'!E20*0.96 -> 5.4639871 | L14: mAh | M14: Kapazität nach der Formierung: | N14: 5.0938 | O14: mAh | P14: N:P-Verhältnis: | Q14: =((E14*1000-'Material - Abmessungen'!E17-('Material - Abmessungen'!E49*1000))*'Material - Abmessungen'!E10*0.697)/K14 -> 3.4841576 | R14: Lithiierung der Anode: | S14: =Q14^(-1) -> 0.28701343
B15: df_MH_MA_VZ_3,8_10µm_1h_12 | D15: 6.Anode: | E15: 0.0251 | F15: g | G15: 6.Kathode: | H15: 0.0371 | I15: g | J15: berechnete/theoretische Zellkapazität: | K15: =(H15*1000-'Material - Abmessungen'!E25)*'Material - Abmessungen'!E20*0.96 -> 5.4817471 | L15: mAh | M15: Kapazität nach der Formierung: | N15: 5.0602 | O15: mAh | P15: N:P-Verhältnis: | Q15: =((E15*1000-'Material - Abmessungen'!E17-('Material - Abmessungen'!E49*1000))*'Material - Abmessungen'!E10*0.697)/K15 -> 3.4273627 | R15: Lithiierung der Anode: | S15: =Q15^(-1) -> 0.29176953
D17: Coulombsche Wirkungsgrade:
F18: 1. Zelle | G18: 2. Zelle | H18: 3. Zelle | I18: 4. Zelle | J18: 5. Zelle | K18: 6.Zelle
D19: 1. Laden (CC): | F19: 6.3771 | G19: 6.213 | H19: 6.2987 | I19: 6.3074 | J19: 6.2633 | K19: 6.2479
D20: 2. Laden (CV): | F20: 0.1167 | G20: 0.1281 | H20: 0.1199 | I20: 0.1131 | J20: 0.1133 | K20: 0.1262
D21: 1. Entladen (CC): | F21: 5.1819 | G21: 5.012 | H21: 5.1622 | I21: 5.1591 | J21: 5.1127 | K21: 5.0875 | O21: Standardabweichung
D22: Coulombscher Wirkungsgrad: | F22: =F21/(F19+F20) -> 0.79797653 | G22: =G21/(G19+G20) -> 0.79039914 | H22: =H21/(H19+H20) -> 0.80425638 | I22: =I21/(I19+I20) -> 0.80353555 | J22: =J21/(J19+J20) -> 0.80179092 | K22: =K21/(K19+K20) -> 0.7981519 | L22: Durchschnittlicher ICE: | M22: =(F22+G22+H22+I22+J22+K22)/6 -> 0.79935174 | O22: =_xlfn.STDEV.S(F22,G22,H22,I22,J22,K22) -> 0.0051183827
D24: 3. Laden (CC): | F24: 5.1263 | G24: 4.9461 | H24: 5.1029 | I24: 5.1018 | J24: 5.0541 | K24: 5.0168
D25: 4. Laden (CV): | F25: 0.0981 | G25: 0.1083 | H25: 0.1014 | I25: 0.0974 | J25: 0.0988 | K25: 0.1112
D26: 2. Entladen (CC): | F26: 5.1619 | G26: 4.9853 | H26: 5.1486 | I26: 5.1427 | J26: 5.0938 | K26: 5.0603 | O26: Standardabweichung
D27: Coulombscher Wirkungsgrad: | F27: =F26/(F24+F25) -> 0.9880369 | G27: =G26/(G24+G25) -> 0.98632874 | H27: =H26/(H24+H25) -> 0.98929731 | I27: =I26/(I24+I25) -> 0.98913294 | J27: =J26/(J24+J25) -> 0.98853073 | K27: =K26/(K24+K25) -> 0.98679797 | L27: Durchschnittlicher ICE: | M27: =(F27+G27+H27+I27+J27+K27)/6 -> 0.98802077 | O27: =_xlfn.STDEV.S(F27,G27,H27,I27,J27,K27) -> 0.0012235194
B30: Prälithiiert - 10µm - 24h Stunden
B31: Atmosphäre während der Prälithiierung: | C31: O2: <2 ppm | D31: H2O: <2 ppm
C33: Atmosphäre während der Assemblierung: | G33: O2: <1,0 ppm | H33: O2: <1,0 ppm
B35: df_MH_MA_VZ_3,8_10µm_24h_1 | D35: 1. Anode: | E35: 0.0252 | F35: g | G35: 1. Kathode: | H35: 0.0358 | I35: g | J35: berechnete/theoretische Zellkapazität: | K35: =(H35*1000-'Material - Abmessungen'!E25)*'Material - Abmessungen'!E20*0.96 -> 5.2508671 | L35: mAh | M35: Kapazität nach der Formierung: | N35: 4.8296 | O35: mAh | P35: N:P-Verhältnis: | Q35: =((E35*1000-'Material - Abmessungen'!E17-('Material - Abmessungen'!E49*1000))*'Material - Abmessungen'!E10*0.697)/K35 -> 3.6255711 | R35: Lithiierung der Anode: | S35: =Q35^(-1) -> 0.27581862 | T35: Diese Zelle zeigt eine unterdurchschnittliche Performance im Lebensdauertest und wird aus diesem Grund nicht für diese Auswertung herangezogen.
B36: df_MH_MA_VZ_3,8_10µm_24h_2 | D36: 2. Anode: | E36: 0.025 | F36: g | G36: 2. Kathode: | H36: 0.0364 | I36: g | J36: berechnete/theoretische Zellkapazität: | K36: =(H36*1000-'Material - Abmessungen'!E25)*'Material - Abmessungen'!E20*0.96 -> 5.3574271 | L36: mAh | M36: Kapazität nach der Formierung: | N36: 5.068 | O36: mAh | P36: N:P-Verhältnis: | Q36: =((E36*1000-'Material - Abmessungen'!E17-('Material - Abmessungen'!E49*1000))*'Material - Abmessungen'!E10*0.697)/K36 -> 3.4603326 | R36: Lithiierung der Anode: | S36: =Q36^(-1) -> 0.28898956
B37: df_MH_MA_VZ_3,8_10µm_24h_3 | D37: 3. Anode: | E37: 0.0249 | F37: g | G37: 3. Kathode: | H37: 0.0364 | I37: g | J37: berechnete/theoretische Zellkapazität: | K37: =(H37*1000-'Material - Abmessungen'!E25)*'Material - Abmessungen'!E20*0.96 -> 5.3574271 | L37: mAh | M37: Kapazität nach der Formierung: | N37: 5.0819 | O37: mAh | P37: N:P-Verhältnis: | Q37: =((E37*1000-'Material - Abmessungen'!E17-('Material - Abmessungen'!E49*1000))*'Material - Abmessungen'!E10*0.697)/K37 -> 3.4137699 | R37: Lithiierung der Anode: | S37: =Q37^(-1) -> 0.29293129
B38: df_MH_MA_VZ_3,8_10µm_24h_4 | D38: 4.Anode: | E38: 0.0249 | F38: g | G38: 4. Kathode: | H38: 0.0364 | I38: g | J38: berechnete/theoretische Zellkapazität: | K38: =(H38*1000-'Material - Abmessungen'!E25)*'Material - Abmessungen'!E20*0.96 -> 5.3574271 | L38: mAh | M38: Kapazität nach der Formierung: | N38: 5.1615 | O38: mAh | P38: N:P-Verhältnis: | Q38: =((E38*1000-'Material - Abmessungen'!E17-('Material - Abmessungen'!E49*1000))*'Material - Abmessungen'!E10*0.697)/K38 -> 3.4137699 | R38: Lithiierung der Anode: | S38: =Q38^(-1) -> 0.29293129
D40: Coulombsche Wirkungsgrade:
F41: 1. Zelle | G41: 2. Zelle | H41: 3. Zelle | I41: 4. Zelle
D42: 1. Laden (CC): | F42: 5.9607 | G42: 6.1772 | H42: 6.1545 | I42: 6.2064
D43: 2. Laden (CV): | F43: 0.1624 | G43: 0.1228 | H43: 0.1199 | I43: 0.1025
D44: 1. Entladen (CC): | F44: 4.8912 | G44: 5.1006 | H44: 5.1082 | I44: 5.169 | M44: Standardabweichung
D45: Coulombscher Wirkungsgrad: | F45: =F44/(F42+F43) -> 0.79881106 | G45: =G44/(G42+G43) -> 0.80961905 | H45: =H44/(H42+H43) -> 0.81413362 | I45: =I44/(I42+I43) -> 0.81931874 | J45: Durchschnittlicher ICE: | K45: =(G45+H45+I45)/3 -> 0.81435714 | M45: =_xlfn.STDEV.S(G45,H45,I45) -> 0.0048537077
D47: 3. Laden (CC): | F47: 4.7559 | G47: 5.0205 | H47: 5.0347 | I47: 5.1189
D48: 4. Laden (CV): | F48: 0.1662 | G48: 0.1141 | H48: 0.1106 | I48: 0.0908
D49: 2. Entladen (CC): | F49: 4.8296 | G49: 5.068 | H49: 5.0819 | I49: 5.1615 | M49: Standardabweichung
D50: Coulombscher Wirkungsgrad: | F50: =F49/(F47+F48) -> 0.98120721 | G50: =G49/(G47+G48) -> 0.98702917 | H50: =H49/(H47+H48) -> 0.98767808 | I50: =I49/(I47+I48) -> 0.99074803 | J50: Durchschnittlicher ICE: | K50: =(G50+H50+I50)/3 -> 0.98848509 | M50: =_xlfn.STDEV.S(G50,H50,I50) -> 0.0019864352
B53: Prälithiiert - 10µm - 48h Stunden
B54: Atmosphäre während der Prälithiierung: | C54: O2: <2 ppm | D54: H2O: <2 ppm
C56: Atmosphäre während der Assemblierung: | G56: O2: <1,0 ppm | H56: O2: <1,0 ppm
...

Sheet Vollzelle - Pouchzelle (10µm)
B2: Pouchzellen zur Untersuchung der Auswirkungen unterschiedlicher Prälithiierungsdrücke
B5: Unprälithiiert - 0,2MPa - 48h
B6: Atmosphäre während der Prälithiierung: | C6: O2: <2 ppm | D6: H2O: <2 ppm
C8: Atmosphäre während der Assemblierung: | G8: O2: <1,0 ppm | H8: O2: <1,0 ppm
B10: df_MH_VZ_PZ_3,8_Ref_48h_1 | D10: 1. Anode: | E10: 0.1637 | F10: g | G10: 1. Kathode: | H10: 0.1999 | I10: g | J10: berechnete/theoretische Zellkapazität: | K10: =(H10*1000-'Material - Abmessungen'!E33)*'Material - Abmessungen'!E28*0.96 -> 30.397538 | L10: mAh | M10: Kapazität nach der Formierung: | N10: 28.542 | O10: mAh | P10: N:P-Verhältnis: | Q10: =((E10*1000-'Material - Abmessungen'!E44-('Material - Abmessungen'!E49*1000))*'Material - Abmessungen'!E38*0.697)/K10 -> 3.974908 | R10: Lithiierung der Anode: | S10: =Q10^(-1) -> 0.25157815
B11: df_MH_VZ_PZ_3,8_Ref_48h_2 | D11: 2. Anode: | E11: 0.1602 | F11: g | G11: 2. Kathode: | H11: 0.1994 | I11: g | J11: berechnete/theoretische Zellkapazität: | K11: =(H11*1000-'Material - Abmessungen'!E33)*'Material - Abmessungen'!E28*0.96 -> 30.306338 | L11: mAh | M11: Kapazität nach der Formierung: | N11: 28.379 | O11: mAh | P11: N:P-Verhältnis: | Q11: =((E11*1000-'Material - Abmessungen'!E44-('Material - Abmessungen'!E49*1000))*'Material - Abmessungen'!E38*0.697)/K11 -> 3.698779 | R11: Lithiierung der Anode: | S11: =Q11^(-1) -> 0.27035949
B12: df_MH_VZ_PZ_3,8_Ref_48h_3 | D12: 3. Anode: | E12: 0.1608 | F12: g | G12: 3. Kathode: | H12: 0.1999 | I12: g | J12: berechnete/theoretische Zellkapazität: | K12: =(H12*1000-'Material - Abmessungen'!E33)*'Material - Abmessungen'!E28*0.96 -> 30.397538 | L12: mAh | M12: Kapazität nach der Formierung: | N12: 28.529 | O12: mAh | P12: N:P-Verhältnis: | Q12: =((E12*1000-'Material - Abmessungen'!E44-('Material - Abmessungen'!E49*1000))*'Material - Abmessungen'!E38*0.697)/K12 -> 3.7369206 | R12: Lithiierung der Anode: | S12: =Q12^(-1) -> 0.26760001
D14: Coulombsche Wirkungsgrade:
F15: 1. Zelle | G15: 2. Zelle | H15: 3. Zelle
D16: 1. Laden (CC): | F16: 36.444 | G16: 36.07 | H16: 36.276
D17: 2. Laden (CV): | F17: 0.5331 | G17: 0.778 | H17: 0.562
D18: 1. Entladen (CC): | F18: 28.872 | G18: 28.684 | H18: 28.8 | O18: Standardabweichung
D19: Coulombscher Wirkungsgrad: | F19: =F18/(F16+F17) -> 0.78080758 | G19: =G18/(G16+G17) -> 0.77844116 | H19: =H18/(H16+H17) -> 0.7818014 | L19: Durchschnittlicher ICE: | M19: =(F19+G19+H19)/3 -> 0.78035005 | O19: =_xlfn.STDEV.S(F19,G19,H19) -> 0.0017262098
D21: 3. Laden (CC): | F21: 28.686 | G21: 28.438 | H21: 28.664
D22: 4. Laden (CV): | F22: 0.426 | G22: 0.5142 | H22: 0.427
D23: 2. Entladen (CC): | F23: 28.542 | G23: 28.379 | H23: 28.529 | O23: Standardabweichung
D24: Coulombscher Wirkungsgrad: | F24: =F23/(F21+F22) -> 0.98042045 | G24: =G23/(G21+G22) -> 0.98020185 | H24: =H23/(H21+H22) -> 0.98068131 | L24: Durchschnittlicher ICE: | M24: =(F24+G24+H24)/3 -> 0.98043454 | O24: =_xlfn.STDEV.S(F24,G24,H24) -> 0.00024004056
B27: Prälithiiert - 0MPa - 48h
B28: Atmosphäre während der Prälithiierung: | C28: O2: <2 ppm | D28: H2O: <2 ppm
C30: Atmosphäre während der Assemblierung: | G30: O2: <1,0 ppm | H30: O2: <1,0 ppm
B32: df_MH_VZ_PZ_3,8_10µm_48h_0b_1 | D32: 1. Anode: | E32: 0.1587 | F32: g | G32: 1. Kathode: | H32: 0.1993 | I32: g | J32: berechnete/theoretische Zellkapazität: | K32: =(H32*1000-'Material - Abmessungen'!E33)*'Material - Abmessungen'!E28*0.96 -> 30.288098 | L32: mAh | M32: Kapazität nach der Formierung: | N32: 29.098 | O32: mAh | P32: N:P-Verhältnis: | Q32: =((E32*1000-'Material - Abmessungen'!E44-('Material - Abmessungen'!E49*1000))*'Material - Abmessungen'!E38*0.697)/K32 -> 3.5774647 | R32: Lithiierung der Anode: | S32: =Q32^(-1) -> 0.27952756
B33: df_MH_VZ_PZ_3,8_10µm_48h_0b_2 | D33: 2. Anode: | E33: 0.1602 | F33: g | G33: 2. Kathode: | H33: 0.1996 | I33: g | J33: berechnete/theoretische Zellkapazität: | K33: =(H33*1000-'Material - Abmessungen'!E33)*'Material - Abmessungen'!E28*0.96 -> 30.342818 | L33: mAh | M33: Kapazität nach der Formierung: | N33: 29.403 | O33: mAh | P33: N:P-Verhältnis: | Q33: =((E33*1000-'Material - Abmessungen'!E44-('Material - Abmessungen'!E49*1000))*'Material - Abmessungen'!E38*0.697)/K33 -> 3.6943321 | R33: Lithiierung der Anode: | S33: =Q33^(-1) -> 0.27068492
D35: Coulombsche Wirkungsgrade:
F36: 1. Zelle | G36: 2. Zelle
D37: 1. Laden (CC): | F37: 32.824 | G37: 33.402
D38: 2. Laden (CV): | F38: 2.068 | G38: 2.105
D39: 1. Entladen (CC): | F39: 28.976 | G39: 29.4 | O39: Standardabweichung
D40: Coulombscher Wirkungsgrad: | F40: =F39/(F37+F38) -> 0.83044824 | G40: =G39/(G37+G38) -> 0.82800575 | L40: Durchschnittlicher ICE: | M40: =(F40+G40)/2 -> 0.82922699 | O40: =_xlfn.STDEV.S(F40,G40,H40) -> 0.0017271047
D42: 3. Laden (CC): | F42: 28.764 | G42: 28.56
D43: 4. Laden (CV): | F43: 1.192 | G43: 1.43
D44: 2. Entladen (CC): | F44: 29.098 | G44: 29.403 | O44: Standardabweichung
D45: Coulombscher Wirkungsgrad: | F45: =F44/(F42+F43) -> 0.97135799 | G45: =G44/(G42+G43) -> 0.98042681 | L45: Durchschnittlicher ICE: | M45: =(F45+G45)/2 -> 0.9758924 | O45: =_xlfn.STDEV.S(F45,G45,H45) -> 0.0064126222
B47: Prälithiiert - 1MPa - 48h
B48: Atmosphäre während der Prälithiierung: | C48: O2: <2 ppm | D48: H2O: <2 ppm
C50: Atmosphäre während der Assemblierung: | G50: O2: <1,0 ppm | H50: O2: <1,0 ppm
B52: df_MH_VZ_PZ_3,8_10µm_48h_1b_1 | D52: 1. Anode: | E52: 0.1585 | F52: g | G52: 1. Kathode: | H52: 0.197 | I52: g | J52: berechnete/theoretische Zellkapazität: | K52: =(H52*1000-'Material - Abmessungen'!E33)*'Material - Abmessungen'!E28*0.96 -> 29.868578 | L52: mAh | M52: Kapazität nach der Formierung: | N52: 32.117 | O52: mAh | P52: N:P-Verhältnis: | Q52: =((E52*1000-'Material - Abmessungen'!E44-('Material - Abmessungen'!E49*1000))*'Material - Abmessungen'!E38*0.697)/K52 -> 3.6110085 | R52: Lithiierung der Anode: | S52: =Q52^(-1) -> 0.27693094
B53: df_MH_VZ_PZ_3,8_10µm_48h_1b_2 | D53: 2. Anode: | E53: 0.1641 | F53: g | G53: 2. Kathode: | H53: 0.1993 | I53: g | J53: berechnete/theoretische Zellkapazität: | K53: =(H53*1000-'Material - Abmessungen'!E33)*'Material - Abmessungen'!E28*0.96 -> 30.288098 | L53: mAh | M53: Kapazität nach der Formierung: | N53: 32.407 | O53: mAh | P53: N:P-Verhältnis: | Q53: =((E53*1000-'Material - Abmessungen'!E44-('Material - Abmessungen'!E49*1000))*'Material - Abmessungen'!E38*0.697)/K53 -> 4.022215 | R53: Lithiierung der Anode: | S53: =Q53^(-1) -> 0.24861923
D55: Coulombsche Wirkungsgrade:
F56: 1. Zelle | G56: 2. Zelle
D57: 1. Laden (CC): | F57: 35.924 | G57: 36.44
...

Sheet Halbzelle - 10µm (CR2032) - For
B2: Halbzellen zur Untersuchung der Auswirkungen unterschiedlicher Prälithiierungsgrade in Abhängigkeit der Prälithiierungsdauer (10µm)
B5: Prälithiiert - 10µm - 0h Stunden (2 min)
B6: Atmosphäre während der Prälithiierung: | C6: O2: <2 ppm | D6: H2O: <2 ppm
C8: Atmosphäre während der Assemblierung: | G8: O2: <1,0 ppm | H8: O2: <12,0 ppm
B10: df_MH_MA_VV_HZ_Prä_0h_1 | D10: 1. Anode: | E10: 0.02551 | F10: g | G10: theoretische Kapazität der Anode: | H10: ='Material - Abmessungen'!E15 -> 6.7149563 | I10: mAh
B11: df_MH_MA_VV_HZ_Prä_0h_2 | D11: 2. Anode: | E11: 0.02526 | F11: g | G11: theoretische Kapazität der Anode: | H11: ='Material - Abmessungen'!E15 -> 6.7149563 | I11: mAh
B12: df_MH_MA_VV_HZ_Prä_0h_3 | D12: 3. Anode: | E12: 0.02601 | F12: g | G12: theoretische Kapazität der Anode: | H12: ='Material - Abmessungen'!E15 -> 6.7149563 | I12: mAh
D14: Coulombsche Wirkungsgrade:
F15: 1. Zelle | G15: 2. Zelle | H15: 3. Zelle
D16: 1. Laden (CC): | F16: 6.715 | G16: 6.715 | H16: 6.715
D17: 2. Laden (CV): | F17: 0 | G17: 0 | H17: 0
D18: 1. Entladen (CC): | F18: 9.118 | G18: 9.182 | H18: 9.049 | M18: Standardabweichung
D19: Coulombscher Wirkungsgrad: | F19: =F18/(F16+F17) -> 1.3578555 | G19: =G18/(G16+G17) -> 1.3673864 | H19: =H18/(H16+H17) -> 1.34758 | J19: Durchschnittlicher ICE: | K19: =(F19+G19+H19)/3 -> 1.3576073 | M19: =_xlfn.STDEV.S(F19,G19,H19) -> 0.0099055342
D21: 3. Laden (CC): | F21: 6.715 | G21: 6.715 | H21: 6.715
D22: 4. Laden (CV): | F22: 0 | G22: 0 | H22: 0
D23: 2. Entladen (CC): | F23: 6.643 | G23: 6.652 | H23: 6.645 | M23: Standardabweichung
D24: Coulombscher Wirkungsgrad: | F24: =F23/(F21+F22) -> 0.98927774 | G24: =G23/(G21+G22) -> 0.99061802 | H24: =H23/(H21+H22) -> 0.98957558 | J24: Durchschnittlicher ICE: | K24: =(F24+G24+H24)/3 -> 0.98982378 | M24: =_xlfn.STDEV.S(F24,G24,H24) -> 0.00070377001
D26: Niedrigste Spannungswerte der Halbzellen
D27: 1. Anode: | E27: -0.2295 | F27: V
D28: 2. Anode: | E28: -0.2712 | F28: V
D29: 3. Anode: | E29: -0.0433 | F29: V
D30: Mittelwert: | E30: =(E27+E28+E29)/3 -> -0.18133333 | F30: V
D32: Niedrigste Spannungswerte der Halbzellen
D33: 1. Anode: | E33: 0.12 | F33: h
D34: 2. Anode: | E34: 0.07 | F34: h
D35: 3. Anode: | E35: 0.41 | F35: h
D36: Mittelwert: | E36: =(E33+E34+E35)/3 -> 0.2 | F36: h
B38: Prälithiiert - 10µm - 24h Stunden
B39: Atmosphäre während der Prälithiierung: | C39: O2: <2 ppm | D39: H2O: <2 ppm
C41: Atmosphäre während der Assemblierung: | G41: O2: <1,0 ppm | H41: O2: <12,0 ppm
B43: df_MH_MA_VV_HZ_Prä_24h_1 | D43: 1. Anode: | E43: 0.02547 | F43: g | G43: theoretische Kapazität der Anode: | H43: ='Material - Abmessungen'!E15 -> 6.7149563 | I43: mAh
B44: df_MH_MA_VV_HZ_Prä_24h_2 | D44: 2. Anode: | E44: 0.02541 | F44: g | G44: theoretische Kapazität der Anode: | H44: ='Material - Abmessungen'!E15 -> 6.7149563 | I44: mAh
B45: df_MH_MA_VV_HZ_Prä_24h_3 | D45: 3. Anode: | E45: 0.02544 | F45: g | G45: theoretische Kapazität der Anode: | H45: ='Material - Abmessungen'!E15 -> 6.7149563 | I45: mAh
D47: Coulombsche Wirkungsgrade:
F48: 1. Zelle | G48: 2. Zelle | H48: 3. Zelle
D49: 1. Laden (CC): | F49: 6.715 | G49: 6.715 | H49: 6.715
D50: 2. Laden (CV): | F50: 0 | G50: 0 | H50: 0
D51: 1. Entladen (CC): | F51: 9.189 | G51: 9.132 | H51: 9.211 | M51: Standardabweichung
D52: Coulombscher Wirkungsgrad: | F52: =F51/(F49+F50) -> 1.3684289 | G52: =G51/(G49+G50) -> 1.3599404 | H52: =H51/(H49+H50) -> 1.3717051 | J52: Durchschnittlicher ICE: | K52: =(F52+G52+H52)/3 -> 1.3666915 | M52: =_xlfn.STDEV.S(F52,G52,H52) -> 0.0060717382
D54: 3. Laden (CC): | F54: 6.715 | G54: 6.715 | H54: 6.715
...

Sheet Halbzelle - 5µm (CR2032) - For
B2: Halbzellen zur Untersuchung der Auswirkungen unterschiedlicher Prälithiierungsgrade in Abhängigkeit der Prälithiierungsdauer (5µm)
B5: Prälithiiert - 5µm - 0h Stunden (2 min)
B6: Atmosphäre während der Prälithiierung: | C6: O2: <2 ppm | D6: H2O: <2 ppm
C8: Atmosphäre während der Assemblierung: | G8: O2: <1,0 ppm | H8: O2: <12,0 ppm
B10: df_MH_MA_VV_HZ_Prä_0h_5_1 | D10: 1. Anode: | E10: 0.02496 | F10: g | G10: theoretische Kapazität der Anode: | H10: ='Material - Abmessungen'!E15 -> 6.7149563 | I10: mAh
B11: df_MH_MA_VV_HZ_Prä_0h_5_2 | D11: 2. Anode: | E11: 0.02524 | F11: g | G11: theoretische Kapazität der Anode: | H11: ='Material - Abmessungen'!E15 -> 6.7149563 | I11: mAh
B12: df_MH_MA_VV_HZ_Prä_0h_5_3 | D12: 3. Anode: | E12: 0.02504 | F12: g | G12: theoretische Kapazität der Anode: | H12: ='Material - Abmessungen'!E15 -> 6.7149563 | I12: mAh
D14: Coulombsche Wirkungsgrade:
F15: 1. Zelle | G15: 2. Zelle | H15: 3. Zelle
D16: 1. Laden (CC): | F16: 6.715 | G16: 6.715 | H16: 6.715
D17: 2. Laden (CV): | F17: 0 | G17: 0 | H17: 0
D18: 1. Entladen (CC): | F18: 7.948 | G18: 8.014 | H18: 8.004 | M18: Standardabweichung
D19: Coulombscher Wirkungsgrad: | F19: =F18/(F16+F17) -> 1.1836188 | G19: =G18/(G16+G17) -> 1.1934475 | H19: =H18/(H16+H17) -> 1.1919583 | J19: Durchschnittlicher ICE: | K19: =(F19+G19+H19)/3 -> 1.1896749 | M19: =_xlfn.STDEV.S(F19,G19,H19) -> 0.005297323
D21: 3. Laden (CC): | F21: 6.715 | G21: 6.715 | H21: 6.715
D22: 4. Laden (CV): | F22: 0 | G22: 0 | H22: 0
D23: 2. Entladen (CC): | F23: 6.633 | G23: 6.645 | H23: 6.638 | M23: Standardabweichung
D24: Coulombscher Wirkungsgrad: | F24: =F23/(F21+F22) -> 0.98778853 | G24: =G23/(G21+G22) -> 0.98957558 | H24: =H23/(H21+H22) -> 0.98853313 | J24: Durchschnittlicher ICE: | K24: =(F24+G24+H24)/3 -> 0.98863241 | M24: =_xlfn.STDEV.S(F24,G24,H24) -> 0.00089764911
D26: Niedrigste Spannungswerte der Halbzellen
D27: 1. Anode: | E27: -0.2514 | F27: V
D28: 2. Anode: | E28: -0.2081 | F28: V
D29: 3. Anode: | E29: -0.2146 | F29: V
D30: Mittelwert: | E30: =(E27+E28+E29)/3 -> -0.2247 | F30: V
D32: Niedrigste Spannungswerte der Halbzellen
D33: 1. Anode: | E33: 0.47 | F33: h
D34: 2. Anode: | E34: 0.05 | F34: h
D35: 3. Anode: | E35: 0.05 | F35: h
D36: Mittelwert: | E36: =(E33+E34+E35)/3 -> 0.19 | F36: h
B38: Prälithiiert - 5µm - 24h Stunden
B39: Atmosphäre während der Prälithiierung: | C39: O2: <2 ppm | D39: H2O: <2 ppm
C41: Atmosphäre während der Assemblierung: | G41: O2: <1,0 ppm | H41: O2: <12,0 ppm
B43: df_MH_MA_VV_HZ_Prä_24h_5_1 | D43: 1. Anode: | E43: 0.02518 | F43: g | G43: theoretische Kapazität der Anode: | H43: ='Material - Abmessungen'!E15 -> 6.7149563 | I43: mAh
B44: df_MH_MA_VV_HZ_Prä_24h_5_2 | D44: 2. Anode: | E44: 0.02511 | F44: g | G44: theoretische Kapazität der Anode: | H44: ='Material - Abmessungen'!E15 -> 6.7149563 | I44: mAh
B45: df_MH_MA_VV_HZ_Prä_24h_5_3 | D45: 3. Anode: | E45: 0.02506 | F45: g | G45: theoretische Kapazität der Anode: | H45: ='Material - Abmessungen'!E15 -> 6.7149563 | I45: mAh
D47: Coulombsche Wirkungsgrade:
F48: 1. Zelle | G48: 2. Zelle | H48: 3. Zelle
D49: 1. Laden (CC): | F49: 6.715 | G49: 6.715 | H49: 6.715
D50: 2. Laden (CV): | F50: 0 | G50: 0 | H50: 0
D51: 1. Entladen (CC): | F51: 7.941 | G51: 7.983 | H51: 7.935 | M51: Standardabweichung
D52: Coulombscher Wirkungsgrad: | F52: =F51/(F49+F50) -> 1.1825763 | G52: =G51/(G49+G50) -> 1.188831 | H52: =H51/(H49+H50) -> 1.1816828 | J52: Durchschnittlicher ICE: | K52: =(F52+G52+H52)/3 -> 1.1843634 | M52: =_xlfn.STDEV.S(F52,G52,H52) -> 0.003894772
D54: 3. Laden (CC): | F54: 6.715 | G54: 6.715 | H54: 6.715
...

Sheet Halbzelle - Ref (CR2032) - For
B2: Unprälithiierte Referenzhalbzellen zur Untersuchung der Auswirkungen unterschiedlicher Prälithiierungsgrade in Abhängigkeit der Prälithiierungsdauer
B3: Diese Ref-Zellen schaffen einen Bezug inwieweit sich die Prälithiierung auf die Formierung auswirkt
B5: Unprälithiiert - Ref - 0h Stunden (2 min)
C8: Atmosphäre während der Assemblierung: | G8: O2: <1,0 ppm | H8: O2: <12,0 ppm
B10: df_MH_MA_VV_HZ_Prä_0h_5_1 | D10: 1. Anode: | E10: 0.02447 | F10: g | G10: theoretische Kapazität der Anode: | H10: ='Material - Abmessungen'!E15 -> 6.7149563 | I10: mAh
B11: df_MH_MA_VV_HZ_Prä_0h_5_2 | D11: 2. Anode: | E11: 0.02438 | F11: g | G11: theoretische Kapazität der Anode: | H11: ='Material - Abmessungen'!E15 -> 6.7149563 | I11: mAh
B12: df_MH_MA_VV_HZ_Prä_0h_5_3 | D12: 3. Anode: | E12: 0.02421 | F12: g | G12: theoretische Kapazität der Anode: | H12: ='Material - Abmessungen'!E15 -> 6.7149563 | I12: mAh
D14: Coulombsche Wirkungsgrade:
F15: 1. Zelle | G15: 2. Zelle | H15: 3. Zelle
D16: 1. Laden (CC): | F16: 6.715 | G16: 6.715 | H16: 6.715
D17: 2. Laden (CV): | F17: 0 | G17: 0 | H17: 0
D18: 1. Entladen (CC): | F18: 6.208 | G18: 6.192 | H18: 6.193 | M18: Standardabweichung
D19: Coulombscher Wirkungsgrad: | F19: =F18/(F16+F17) -> 0.92449739 | G19: =G18/(G16+G17) -> 0.92211467 | H19: =H18/(H16+H17) -> 0.92226359 | J19: Durchschnittlicher ICE: | K19: =(F19+G19+H19)/3 -> 0.92295855 | M19: =_xlfn.STDEV.S(F19,G19,H19) -> 0.001334756
D21: 3. Laden (CC): | F21: 6.715 | G21: 6.715 | H21: 6.715
D22: 4. Laden (CV): | F22: 0 | G22: 0 | H22: 0
D23: 2. Entladen (CC): | F23: 6.618 | G23: 6.618 | H23: 6.62 | M23: Standardabweichung
D24: Coulombscher Wirkungsgrad: | F24: =F23/(F21+F22) -> 0.98555473 | G24: =G23/(G21+G22) -> 0.98555473 | H24: =H23/(H21+H22) -> 0.98585257 | J24: Durchschnittlicher ICE: | K24: =(F24+G24+H24)/3 -> 0.98565401 | M24: =_xlfn.STDEV.S(F24,G24,H24) -> 0.00017195838

Sheet Halbzelle - 10µm - EIS
B2: Halbzellen zur Untersuchung der Veränderung des internen Zellwiderstandes zur PEIS-Messungen über einen Zeitraum von 336 Stunden (10 µm) bei einer Temperatur von 25°C
B5: Prälithiiert - 10µm - PEIS-Messungen mittels der BioLogic (VSP-3e)
B6: Atmosphäre während der Prälithiierung: | C6: O2: <2 ppm | D6: H2O: <2 ppm
C8: Atmosphäre während der Assemblierung: | G8: O2: <1,0 ppm | H8: O2: <12,0 ppm
B10: df_MH_MA_VV_HZ_EIS_10µm_3,8mAh_1 | D10: 1. Anode: | E10: 0.02573 | F10: g
B11: df_MH_MA_VV_HZ_EIS_10µm_3,8mAh_2 | D11: 2. Anode: | E11: 0.02566 | F11: g | G11: Nicht verwendet, da die Zelle früher gestoppt wurde
B12: df_MH_MA_VV_HZ_EIS_10µm_3,8mAh_3 | D12: 3. Anode: | E12: 0.02561 | F12: g
B13: df_MH_MA_VV_HZ_EIS_10µm_3,8mAh_4 | D13: 4. Anode | E13: 0.02549 | F13: g

Sheet Halbzelle - 5µm - EIS
B2: Halbzellen zur Untersuchung der Veränderung des internen Zellwiderstandes zur PEIS-Messungen über einen Zeitraum von 336 Stunden (5 µm) bei einer Temperatur von 25°C
B5: Prälithiiert - 5µm - PEIS-Messungen mittels der BioLogic (VSP-3e)
B6: Atmosphäre während der Prälithiierung: | C6: O2: <2 ppm | D6: H2O: <2 ppm
C8: Atmosphäre während der Assemblierung: | G8: O2: <1,0 ppm | H8: O2: <12,0 ppm
B10: df_MH_MA_VV_HZ_EIS_5µm_3,8mAh_1 | D10: 1. Anode: | E10: 0.02529 | F10: g
B11: df_MH_MA_VV_HZ_EIS_5µm_3,8mAh_2 | D11: 2. Anode: | E11: 0.02513 | F11: g | G11: Nicht verwendet weil diese Zelle früher gestoppt wurde
B12: df_MH_MA_VV_HZ_EIS_5µm_3,8mAh_3 | D12: 3. Anode: | E12: 0.02529 | F12: g
B13: df_MH_MA_VV_HZ_EIS_5µm_3,8mAh_4 | D13: 4. Anode | E13: 0.02529 | F13: g

Sheet Halbzelle - 10µm - 35°C - EIS
B2: Halbzellen zur Untersuchung der Veränderung des internen Zellwiderstandes zur PEIS-Messungen über einen Zeitraum von 300 Stunden (10 µm) bei einer Temperatur von 35°C
B5: Prälithiiert - 10µm - PEIS-Messungen mittels der BioLogic (VSP-3e) bei einer erhöhten Temperatur von 35°C
B6: Atmosphäre während der Prälithiierung: | C6: O2: <2 ppm | D6: H2O: <2 ppm
C8: Atmosphäre während der Assemblierung: | G8: O2: <1,0 ppm | H8: O2: <12,0 ppm
B10: df_MH_MA_VV_HZ_EIS_10µm_3,8mAh_35°C_1 | D10: 1. Anode: | E10: 0.0249 | F10: g
B11: df_MH_MA_VV_HZ_EIS_10µm_3,8mAh_35°C_2 | D11: 2. Anode: | E11: 0.0248 | F11: g
B12: df_MH_MA_VV_HZ_EIS_10µm_3,8mAh_35°C_3 | D12: 3. Anode: | E12: 0.025 | F12: g
B13: df_MH_MA_VV_HZ_EIS_10µm_3,8mAh_35°C_4 | D13: 4. Anode | E13: 0.0248 | F13: g

Sheet Halbzelle - Ref - EIS
B2: Unprälithiierte Referenzhalbzellen zur Untersuchung der Veränderung des internen Zellwiderstandes zur PEIS-Messungen über einen Zeitraum von 336 Stunden bei einer Temperatur von 25°C
B5: Unprälithiiert - PEIS-Messungen mittels der BioLogic (VSP-3e) bei einer gängigen Temperatur von 25°C
C8: Atmosphäre während der Assemblierung: | G8: O2: <1,0 ppm | H8: O2: <12,0 ppm
B10: df_MH_MA_VV_HZ_EIS_Ref_Unpräli_3,8mAh_1 | D10: 1. Anode: | E10: 0.0238 | F10: g
B11: df_MH_MA_VV_HZ_EIS_Ref_Unpräli_3,8mAh_2 | D11: 2. Anode: | E11: 0.0237 | F11: g
B12: df_MH_MA_VV_HZ_EIS_Ref_Unpräli_3,8mAh_3 | D12: 3. Anode: | E12: 0.0238 | F12: g
B13: df_MH_MA_VV_HZ_EIS_Ref_Unpräli_3,8mAh_4 | D13: 4. Anode | E13: 0.0237 | F13: g

Sheet Vollzellen - 10µm - EIS
B2: Untersuchung der Veränderung des zellinternen Widerstandes prälithiierter (10µm) Vollzellen bei einer gängigen Temperatur von 25°C
B5: Prälithiiert - 10µm - PEIS-Messungen mittels der BioLogic (BCS-910) bei einer gängigen Temperatur von 25°C
B6: Atmosphäre während der Prälithiierung: | C6: O2: <2 ppm | D6: H2O: <2 ppm
C8: Atmosphäre während der Assemblierung: | G8: O2: 1,0 ppm | H8: O2: <1,0 ppm
B10: 2026-01-02_19-42-21_df_MA_Hüesker_df_MH_MA_VZ_3.8_SiG_NCA_1_C.1 | D10: 1. Anode: | E10: 0.025 | F10: g | G10: 1. Kathode: | H10: 0.0366 | I10: g
B11: 2026-01-02_19-42-21_df_MA_Hüesker_df_MH_MA_VZ_3.8_SiG_NCA_2.1_C.2 | D11: 2. Anode: | E11: 0.0249 | F11: g | G11: 2. Kathode: | H11: 0.0368 | I11: g
B12: 2026-01-02_19-42-21_df_MA_Hüesker_df_MH_MA_VZ_3.8_SiG_NCA_3_C.3 | D12: 3. Anode: | E12: 0.0252 | F12: g | G12: 3. Kathode: | H12: 0.036 | I12: g
B13: 2026-01-02_19-42-21_df_MA_Hüesker_df_MH_MA_VZ_3.8_SiG_NCA_4_C.4 | D13: 4.Anode: | E13: 0.0251 | F13: g | G13: 4. Kathode: | H13: 0.0363 | I13: g

Sheet Vollzellen - 5µm - EIS
B2: Untersuchung der Veränderung des zellinternen Widerstandes prälithiierter (5µm) Vollzellen bei einer gängigen Temperatur von 25°C
B5: Prälithiiert - 5µm - PEIS-Messungen mittels der BioLogic (BCS-910) bei einer gängigen Temperatur von 25°C
B6: Atmosphäre während der Prälithiierung: | C6: O2: <2 ppm | D6: H2O: <2 ppm
C8: Atmosphäre während der Assemblierung: | G8: O2: 1,0 ppm | H8: O2: <1,0 ppm
B10: 2026-01-02_19-42-21_df_MA_Hüesker_df_MH_MA_VZ_3.8_5µm_SiG_NCA_3_C.7 | D10: 1. Anode: | E10: 0.0242 | F10: g | G10: 1. Kathode: | H10: 0.0367 | I10: g
B11: 2026-01-02_19-42-21_df_MA_Hüesker_df_MH_MA_VZ_3.8_5µm_SiG_NCA_4_C.8 | D11: 2. Anode: | E11: 0.0246 | F11: g | G11: 2. Kathode: | H11: 0.037 | I11: g
B12: 2026-01-02_19-42-21_df_MA_Hüesker_df_MH_MA_VZ_3.8_5µm_SiG_NCA_5_C.5 | D12: 3. Anode: | E12: 0.0247 | F12: g | G12: 3. Kathode: | H12: 0.0372 | I12: g
B13: 2026-01-02_19-42-21_df_MA_Hüesker_df_MH_MA_VZ_3.8_5µm_SiG_NCA_6_C.6 | D13: 4.Anode: | E13: 0.0246 | F13: g | G13: 4. Kathode: | H13: 0.0374 | I13: g

Sheet Halbzelle - 5µm - 35°C - EIS
B2: Halbzellen zur Untersuchung der Veränderung des internen Zellwiderstandes zur PEIS-Messungen über einen Zeitraum von 300 Stunden (5 µm) bei einer Temperatur von 35°C
B5: Prälithiiert - 5µm - PEIS-Messungen mittels der BioLogic (VSP-3e) bei einer erhöhten Temperatur von 35°C
B6: Atmosphäre während der Prälithiierung: | C6: O2: <2 ppm | D6: H2O: <2 ppm
C8: Atmosphäre während der Assemblierung: | G8: O2: <1,0 ppm | H8: O2: <12,0 ppm
B10: df_MH_MA_VV_HZ_EIS_5µm_3,8mAh_35°C_1 | D10: 1. Anode: | E10: 0.0246 | F10: g
B11: df_MH_MA_VV_HZ_EIS_5µm_3,8mAh_35°C_2 | D11: 2. Anode: | E11: 0.0245 | F11: g
B12: df_MH_MA_VV_HZ_EIS_5µm_3,8mAh_35°C_3 | D12: 3. Anode: | E12: 0.0243 | F12: g
B13: df_MH_MA_VV_HZ_EIS_5µm_3,8mAh_35°C_4 | D13: 4. Anode | E13: 0.0246 | F13: g

Sheet Vollzelle - 5µm (CR2032) - For
B2: Prälithiierte Vollzellen (5µm) die den Vollfaktoriellen Versuchsplan des Prälithiierungsgrades in Abhängigkeit der Prälithiierungsdauer untersuchen
B5: Prälithiiert - 5µm - 1h Stunden
B6: Atmosphäre während der Prälithiierung: | C6: O2: <2 ppm | D6: H2O: <2 ppm
C8: Atmosphäre während der Assemblierung: | G8: O2: <1,0 ppm | H8: O2: <1,0 ppm
B10: df_MH_MA_VZ_3,8_5µm_1h_1 | D10: 1. Anode: | E10: 0.0249 | F10: g | G10: 1. Kathode: | H10: 0.036 | I10: g | J10: berechnete/theoretische Zellkapazität: | K10: =(H10*1000-'Material - Abmessungen'!E25)*'Material - Abmessungen'!E20*0.96 -> 5.2863871 | L10: mAh | M10: Kapazität nach der Formierung: | N10: 4.951 | O10: mAh | P10: N:P-Verhältnis: | Q10: =((E10*1000-'Material - Abmessungen'!E17-('Material - Abmessungen'!E51*1000))*'Material - Abmessungen'!E10*0.697)/K10 -> 3.6822867 | R10: Lithiierung der Anode: | S10: =Q10^(-1) -> 0.27157038
B11: df_MH_MA_VZ_3,8_5µm_1h_2 | D11: 2. Anode: | E11: 0.0248 | F11: g | G11: 2. Kathode: | H11: 0.036 | I11: g | J11: berechnete/theoretische Zellkapazität: | K11: =(H11*1000-'Material - Abmessungen'!E25)*'Material - Abmessungen'!E20*0.96 -> 5.2863871 | L11: mAh | M11: Kapazität nach der Formierung: | N11: 4.9236 | O11: mAh | P11: N:P-Verhältnis: | Q11: =((E11*1000-'Material - Abmessungen'!E17-('Material - Abmessungen'!E51*1000))*'Material - Abmessungen'!E10*0.697)/K11 -> 3.6350983 | R11: Lithiierung der Anode: | S11: =Q11^(-1) -> 0.27509573
B12: df_MH_MA_VZ_3,8_5µm_1h_3 | D12: 3. Anode: | E12: 0.0248 | F12: g | G12: 3. Kathode: | H12: 0.0362 | I12: g | J12: berechnete/theoretische Zellkapazität: | K12: =(H12*1000-'Material - Abmessungen'!E25)*'Material - Abmessungen'!E20*0.96 -> 5.3219071 | L12: mAh | M12: Kapazität nach der Formierung: | N12: 4.9381 | O12: mAh | P12: N:P-Verhältnis: | Q12: =((E12*1000-'Material - Abmessungen'!E17-('Material - Abmessungen'!E51*1000))*'Material - Abmessungen'!E10*0.697)/K12 -> 3.6108365 | R12: Lithiierung der Anode: | S12: =Q12^(-1) -> 0.27694413
B13: df_MH_MA_VZ_3,8_5µm_1h_4 | D13: 4.Anode: | E13: 0.0249 | F13: g | G13: 4. Kathode: | H13: 0.0362 | I13: g | J13: berechnete/theoretische Zellkapazität: | K13: =(H13*1000-'Material - Abmessungen'!E25)*'Material - Abmessungen'!E20*0.96 -> 5.3219071 | L13: mAh | M13: Kapazität nach der Formierung: | N13: 4.9613 | O13: mAh | P13: N:P-Verhältnis: | Q13: =((E13*1000-'Material - Abmessungen'!E17-('Material - Abmessungen'!E51*1000))*'Material - Abmessungen'!E10*0.697)/K13 -> 3.65771 | R13: Lithiierung der Anode: | S13: =Q13^(-1) -> 0.2733951
D15: Coulombsche Wirkungsgrade:
F16: 1. Zelle | G16: 2. Zelle | H16: 3. Zelle | I16: 4. Zelle
D17: 1. Laden (CC): | F17: 6.1211 | G17: 6.13 | H17: 6.0794 | I17: 6.109
D18: 2. Laden (CV): | F18: 0.1043 | G18: 0.1013 | H18: 0.1013 | I18: 0.1008
D19: 1. Entladen (CC): | F19: 4.9809 | G19: 4.9543 | H19: 4.9616 | I19: 4.9851 | M19: Standardabweichung
D20: Coulombscher Wirkungsgrad: | F20: =F19/(F17+F18) -> 0.80009317 | G20: =G19/(G17+G18) -> 0.79506684 | H20: =H19/(H17+H18) -> 0.80275697 | I20: =I19/(I17+I18) -> 0.80277948 | J20: Durchschnittlicher ICE: | K20: =(F20+G20+H20+I20)/4 -> 0.80017411 | M20: =_xlfn.STDEV.S(F20,G20,H20,I20) -> 0.0036308797
D22: 3. Laden (CC): | F22: 4.9294 | G22: 4.9038 | H22: 4.9148 | I22: 4.9395
D23: 4. Laden (CV): | F23: 0.0943 | G23: 0.094 | H23: 0.0894 | I23: 0.0897
D24: 2. Entladen (CC): | F24: 4.951 | G24: 4.9236 | H24: 4.9381 | I24: 4.9613 | M24: Standardabweichung
D25: Coulombscher Wirkungsgrad: | F25: =F24/(F22+F23) -> 0.98552859 | G25: =G24/(G22+G23) -> 0.98515347 | H25: =H24/(H22+H23) -> 0.9867911 | I25: =I24/(I22+I23) -> 0.98649885 | J25: Durchschnittlicher ICE: | K25: =(F25+G25+H25+I25)/4 -> 0.985993 | M25: =_xlfn.STDEV.S(F25,G25,H25,I25) -> 0.00077745838
B28: Prälithiiert - 5µm - 24h Stunden
B29: Atmosphäre während der Prälithiierung: | C29: O2: <2 ppm | D29: H2O: <2 ppm
C31: Atmosphäre während der Assemblierung: | G31: O2: <1,0 ppm | H31: O2: <1,0 ppm
B33: df_MH_MA_VZ_3,8_5µm_24h_1 | D33: 1. Anode: | E33: 0.0248 | F33: g | G33: 1. Kathode: | H33: 0.0366 | I33: g | J33: berechnete/theoretische Zellkapazität: | K33: =(H33*1000-'Material - Abmessungen'!E25)*'Material - Abmessungen'!E20*0.96 -> 5.3929471 | L33: mAh | M33: Kapazität nach der Formierung: | N33: 4.9497 | O33: mAh | P33: N:P-Verhältnis: | Q33: =((E33*1000-'Material - Abmessungen'!E17-('Material - Abmessungen'!E51*1000))*'Material - Abmessungen'!E10*0.697)/K33 -> 3.5632719 | R33: Lithiierung der Anode: | S33: =Q33^(-1) -> 0.28064095
B34: df_MH_MA_VZ_3,8_5µm_24h_2 | D34: 2. Anode: | E34: 0.0249 | F34: g | G34: 2. Kathode: | H34: 0.0376 | I34: g | J34: berechnete/theoretische Zellkapazität: | K34: =(H34*1000-'Material - Abmessungen'!E25)*'Material - Abmessungen'!E20*0.96 -> 5.5705471 | L34: mAh | M34: Kapazität nach der Formierung: | N34: 4.8948 | O34: mAh | P34: N:P-Verhältnis: | Q34: =((E34*1000-'Material - Abmessungen'!E17-('Material - Abmessungen'!E51*1000))*'Material - Abmessungen'!E10*0.697)/K34 -> 3.494449 | R34: Lithiierung der Anode: | S34: =Q34^(-1) -> 0.28616815
B35: df_MH_MA_VZ_3,8_5µm_24h_3 | D35: 3. Anode: | E35: 0.0249 | F35: g | G35: 3. Kathode: | H35: 0.0363 | I35: g | J35: berechnete/theoretische Zellkapazität: | K35: =(H35*1000-'Material - Abmessungen'!E25)*'Material - Abmessungen'!E20*0.96 -> 5.3396671 | L35: mAh | M35: Kapazität nach der Formierung: | N35: 5.004 | O35: mAh | P35: N:P-Verhältnis: | Q35: =((E35*1000-'Material - Abmessungen'!E17-('Material - Abmessungen'!E51*1000))*'Material - Abmessungen'!E10*0.697)/K35 -> 3.6455443 | R35: Lithiierung der Anode: | S35: =Q35^(-1) -> 0.27430746
B36: df_MH_MA_VZ_3,8_5µm_24h_4 | D36: 4.Anode: | E36: 0.0247 | F36: g | G36: 4. Kathode: | H36: 0.036 | I36: g | J36: berechnete/theoretische Zellkapazität: | K36: =(H36*1000-'Material - Abmessungen'!E25)*'Material - Abmessungen'!E20*0.96 -> 5.2863871 | L36: mAh | M36: Kapazität nach der Formierung: | N36: 4.9321 | O36: mAh | P36: N:P-Verhältnis: | Q36: =((E36*1000-'Material - Abmessungen'!E17-('Material - Abmessungen'!E51*1000))*'Material - Abmessungen'!E10*0.697)/K36 -> 3.5879098 | R36: Lithiierung der Anode: | S36: =Q36^(-1) -> 0.2787138 | T36: Diese Zelle wurde beim Reparieren des Coincellrechners frühzeitig gestoppt. Aus diesem Grund wird sie auch nicht für die Betrachtung der Formierung herangezogen
D38: Coulombsche Wirkungsgrade:
F39: 1. Zelle | G39: 2. Zelle | H39: 3. Zelle | I39: 4. Zelle
D40: 1. Laden (CC): | F40: 6.1379 | G40: 6.1102 | H40: 6.1765 | I40: 6.1157
D41: 2. Laden (CV): | F41: 0.1265 | G41: 0.1263 | H41: 0.103 | I41: 0.1036
D42: 1. Entladen (CC): | F42: 4.9675 | G42: 4.9181 | H42: 5.0241 | I42: 4.9584 | M42: Standardabweichung
D43: Coulombscher Wirkungsgrad: | F43: =F42/(F40+F41) -> 0.79297299 | G43: =G42/(G40+G41) -> 0.78859937 | H43: =H42/(H40+H41) -> 0.80007962 | I43: =I42/(I40+I41) -> 0.79726014 | J43: Durchschnittlicher ICE: | K43: =(F43+G43+H43)/3 -> 0.793884 | M43: =_xlfn.STDEV.S(F43,G43,H43) -> 0.0057940902
D45: 3. Laden (CC): | F45: 4.9096 | G45: 4.8546 | H45: 4.9784 | I45: 4.9095
D46: 4. Laden (CV): | F46: 0.1063 | G46: 0.1095 | H46: 0.0888 | I46: 0.0923
D47: 2. Entladen (CC): | F47: 4.9497 | G47: 4.8948 | H47: 5.004 | I47: 4.9321 | M47: Standardabweichung
D48: Coulombscher Wirkungsgrad: | F48: =F47/(F45+F46) -> 0.98680197 | G48: =G47/(G45+G46) -> 0.98603977 | H48: =H47/(H45+H46) -> 0.98752763 | I48: =I47/(I45+I46) -> 0.98606502 | J48: Durchschnittlicher ICE: | K48: =(F48+G48+H48)/3 -> 0.98678979 | M48: =_xlfn.STDEV.S(F48,G48,H48) -> 0.00074400638
B51: Prälithiiert - 5µm - 48h Stunden
B52: Atmosphäre während der Prälithiierung: | C52: O2: <2 ppm | D52: H2O: <2 ppm
C54: Atmosphäre während der Assemblierung: | G54: O2: <1,0 ppm | H54: O2: <1,0 ppm
B56: df_MH_MA_VZ_3,8_5µm_48h_1 | D56: 1. Anode: | E56: 0.0249 | F56: g | G56: 1. Kathode: | H56: 0.0368 | I56: g | J56: berechnete/theoretische Zellkapazität: | K56: =(H56*1000-'Material - Abmessungen'!E25)*'Material - Abmessungen'!E20*0.96 -> 5.4284671 | L56: mAh | M56: Kapazität nach der Formierung: | N56: 4.8959 | O56: mAh | P56: N:P-Verhältnis: | Q56: =((E56*1000-'Material - Abmessungen'!E17-('Material - Abmessungen'!E51*1000))*'Material - Abmessungen'!E10*0.697)/K56 -> 3.5859097 | R56: Lithiierung der Anode: | S56: =Q56^(-1) -> 0.27886926
B57: df_MH_MA_VZ_3,8_5µm_48h_2 | D57: 2. Anode: | E57: 0.0246 | F57: g | G57: 2. Kathode: | H57: 0.0371 | I57: g | J57: berechnete/theoretische Zellkapazität: | K57: =(H57*1000-'Material - Abmessungen'!E25)*'Material - Abmessungen'!E20*0.96 -> 5.4817471 | L57: mAh | M57: Kapazität nach der Formierung: | N57: 4.9616 | O57: mAh | P57: N:P-Verhältnis: | Q57: =((E57*1000-'Material - Abmessungen'!E17-('Material - Abmessungen'!E51*1000))*'Material - Abmessungen'!E10*0.697)/K57 -> 3.4145362 | R57: Lithiierung der Anode: | S57: =Q57^(-1) -> 0.29286554
...

Sheet Vollzelle - Referenzzelle
B2: Unprälithiierte Referenzvollzellen die den Vollfaktoriellen Versuchsplan des Prälithiierungsgrades in Abhängigkeit der Prälithiierungsdauer untersuchen
B3: Diese sollen Bezug geben, inwieweit die Zellperformance durch die Direktkontakt-Prälithiierung verbessert werden kann
C5: Atmosphäre während der Assemblierung: | G5: O2: <1,0 ppm | H5: O2: <1,0 ppm
B7: df_MH_MA_VZ_3,8_Ref_1h_5 | D7: 1. Anode: | E7: 0.0242 | F7: g | G7: 1. Kathode: | H7: 0.0373 | I7: g | J7: berechnete/theoretische Zellkapazität: | K7: =(H7*1000-'Material - Abmessungen'!E25)*'Material - Abmessungen'!E20*0.96 -> 5.5172671 | L7: mAh | M7: Kapazität nach der Formierung: | N7: 4.7469 | O7: mAh | P7: N:P-Verhältnis: | Q7: =((E7*1000-'Material - Abmessungen'!E17)*'Material - Abmessungen'!E10*0.697)/K7 -> 3.4250234 | R7: Lithiierung der Anode: | S7: =Q7^(-1) -> 0.29196881
B8: df_MH_MA_VZ_3,8_Ref_1h_6 | D8: 2. Anode: | E8: 0.0242 | F8: g | G8: 2. Kathode: | H8: 0.0374 | I8: g | J8: berechnete/theoretische Zellkapazität: | K8: =(H8*1000-'Material - Abmessungen'!E25)*'Material - Abmessungen'!E20*0.96 -> 5.5350271 | L8: mAh | M8: Kapazität nach der Formierung: | N8: 4.7322 | O8: mAh | P8: N:P-Verhältnis: | Q8: =((E8*1000-'Material - Abmessungen'!E17)*'Material - Abmessungen'!E10*0.697)/K8 -> 3.4140336 | R8: Lithiierung der Anode: | S8: =Q8^(-1) -> 0.29290866
B9: df_MH_MA_VZ_3,8_Ref_1h_7 | D9: 3. Anode: | E9: 0.0242 | F9: g | G9: 3. Kathode: | H9: 0.0369 | I9: g | J9: berechnete/theoretische Zellkapazität: | K9: =(H9*1000-'Material - Abmessungen'!E25)*'Material - Abmessungen'!E20*0.96 -> 5.4462271 | L9: mAh | M9: Kapazität nach der Formierung: | N9: 4.5829 | O9: mAh | P9: N:P-Verhältnis: | Q9: =((E9*1000-'Material - Abmessungen'!E17)*'Material - Abmessungen'!E10*0.697)/K9 -> 3.469699 | R9: Lithiierung der Anode: | S9: =Q9^(-1) -> 0.28820944
B10: df_MH_MA_VZ_3,8_Ref_1h_8 | D10: 4.Anode: | E10: 0.0243 | F10: g | G10: 4. Kathode: | H10: 0.037 | I10: g | J10: berechnete/theoretische Zellkapazität: | K10: =(H10*1000-'Material - Abmessungen'!E25)*'Material - Abmessungen'!E20*0.96 -> 5.4639871 | L10: mAh | M10: Kapazität nach der Formierung: | N10: 4.6842 | O10: mAh | P10: N:P-Verhältnis: | Q10: =((E10*1000-'Material - Abmessungen'!E17)*'Material - Abmessungen'!E10*0.697)/K10 -> 3.5040758 | R10: Lithiierung der Anode: | S10: =Q10^(-1) -> 0.28538195
D12: Coulombsche Wirkungsgrade:
F13: 1. Zelle | G13: 2. Zelle | H13: 3. Zelle | I13: 4. Zelle
D14: 1. Laden (CC): | F14: 6.352 | G14: 6.3147 | H14: 6.138 | I14: 6.266
D15: 2. Laden (CV): | F15: 0.1096 | G15: 0.1081 | H15: 0.1055 | I15: 0.1078
D16: 1. Entladen (CC): | F16: 4.8021 | G16: 4.7863 | H16: 4.6355 | I16: 4.7388 | M16: Standardabweichung
D17: Coulombscher Wirkungsgrad: | F17: =F16/(F14+F15) -> 0.74317506 | G17: =G16/(G14+G15) -> 0.74520458 | H17: =H16/(H14+H15) -> 0.74245215 | I17: =I16/(I14+I15) -> 0.74348113 | J17: Durchschnittlicher ICE: | K17: =(F17+G17+H17+I17)/4 -> 0.74357823 | M17: =_xlfn.STDEV.S(F17,G17,H17,I17) -> 0.0011669123
D19: 3. Laden (CC): | F19: 4.7673 | G19: 4.7505 | H19: 4.5993 | I19: 4.7028
D20: 4. Laden (CV): | F20: 0.08879 | G20: 0.0881 | H20: 0.0882 | I20: 0.0886
D21: 2. Entladen (CC): | F21: 4.7469 | G21: 4.7322 | H21: 4.5829 | I21: 4.6842 | M21: Standardabweichung
D22: Coulombscher Wirkungsgrad: | F22: =F21/(F19+F20) -> 0.97751483 | G22: =G21/(G19+G20) -> 0.97801017 | H22: =H21/(H19+H20) -> 0.97768533 | I22: =I21/(I19+I20) -> 0.97762658 | J22: Durchschnittlicher ICE: | K22: =(F22+G22+H22+I22)/4 -> 0.97770923 | M22: =_xlfn.STDEV.S(F22,G22,H22,I22) -> 0.00021272546

Sheet Vollzelle - 10µm - 35°C
B2: Prälithiierte Vollzellen (10µm) die den Einfluss einer erhöhten Prälithiierungstemepratur (35°C) während der Prälithiierungsdauer und der Formierung untersuchen
B5: Prälithiiert - 10µm - 48h Stunden - 35°C
B6: Atmosphäre während der Prälithiierung: | C6: O2: <2 ppm | D6: H2O: <2 ppm
C8: Atmosphäre während der Assemblierung: | G8: O2: <1,0 ppm | H8: O2: <1,0 ppm
B10: df_MH_MA_VZ_3,8_10µm_48h_35°C_1 | D10: 1. Anode: | E10: 0.0252 | F10: g | G10: 1. Kathode: | H10: 0.0373 | I10: g | J10: berechnete/theoretische Zellkapazität: | K10: =(H10*1000-'Material - Abmessungen'!E25)*'Material - Abmessungen'!E20*0.96 -> 5.5172671 | L10: mAh | M10: Kapazität nach der Formierung: | N10: 5.5206 | O10: mAh | P10: N:P-Verhältnis: | Q10: =((E10*1000-'Material - Abmessungen'!E17-('Material - Abmessungen'!E49*1000))*'Material - Abmessungen'!E10*0.697)/K10 -> 3.4505112 | R10: Lithiierung der Anode: | S10: =Q10^(-1) -> 0.28981213
B11: df_MH_MA_VZ_3,8_10µm_48h_35°C_2 | D11: 2. Anode: | E11: 0.0253 | F11: g | G11: 2. Kathode: | H11: 0.0371 | I11: g | J11: berechnete/theoretische Zellkapazität: | K11: =(H11*1000-'Material - Abmessungen'!E25)*'Material - Abmessungen'!E20*0.96 -> 5.4817471 | L11: mAh | M11: Kapazität nach der Formierung: | N11: 5.462 | O11: mAh | P11: N:P-Verhältnis: | Q11: =((E11*1000-'Material - Abmessungen'!E17-('Material - Abmessungen'!E49*1000))*'Material - Abmessungen'!E10*0.697)/K11 -> 3.5183762 | R11: Lithiierung der Anode: | S11: =Q11^(-1) -> 0.28422203
B12: df_MH_MA_VZ_3,8_10µm_48h_35°C_3 | D12: 3. Anode: | E12: 0.0252 | F12: g | G12: 3. Kathode: | H12: 0.0376 | I12: g | J12: berechnete/theoretische Zellkapazität: | K12: =(H12*1000-'Material - Abmessungen'!E25)*'Material - Abmessungen'!E20*0.96 -> 5.5705471 | L12: mAh | M12: Kapazität nach der Formierung: | N12: 5.5758 | O12: mAh | P12: N:P-Verhältnis: | Q12: =((E12*1000-'Material - Abmessungen'!E17-('Material - Abmessungen'!E49*1000))*'Material - Abmessungen'!E10*0.697)/K12 -> 3.4175085 | R12: Lithiierung der Anode: | S12: =Q12^(-1) -> 0.29261083
B13: df_MH_MA_VZ_3,8_10µm_48h_35°C_4 | D13: 4.Anode: | E13: 0.0252 | F13: g | G13: 4. Kathode: | H13: 0.0374 | I13: g | J13: berechnete/theoretische Zellkapazität: | K13: =(H13*1000-'Material - Abmessungen'!E25)*'Material - Abmessungen'!E20*0.96 -> 5.5350271 | L13: mAh | M13: Kapazität nach der Formierung: | N13: 5.4869 | O13: mAh | P13: N:P-Verhältnis: | Q13: =((E13*1000-'Material - Abmessungen'!E17-('Material - Abmessungen'!E49*1000))*'Material - Abmessungen'!E10*0.697)/K13 -> 3.4394397 | R13: Lithiierung der Anode: | S13: =Q13^(-1) -> 0.29074503
B14: df_MH_MA_VZ_3,8_10µm_48h_35°C_5 | D14: 5.Anode: | E14: 0.0253 | F14: g | G14: 5.Kathode: | H14: 0.0374 | I14: g | J14: berechnete/theoretische Zellkapazität: | K14: =(H14*1000-'Material - Abmessungen'!E25)*'Material - Abmessungen'!E20*0.96 -> 5.5350271 | L14: mAh | M14: Kapazität nach der Formierung: | N14: 5.572 | O14: mAh | P14: N:P-Verhältnis: | Q14: =((E14*1000-'Material - Abmessungen'!E17-('Material - Abmessungen'!E49*1000))*'Material - Abmessungen'!E10*0.697)/K14 -> 3.4845084 | R14: Lithiierung der Anode: | S14: =Q14^(-1) -> 0.28698453
B15: df_MH_MA_VZ_3,8_10µm_48h_35°C_6 | D15: 6.Anode: | E15: 0.0252 | F15: g | G15: 6.Kathode: | H15: 0.0375 | I15: g | J15: berechnete/theoretische Zellkapazität: | K15: =(H15*1000-'Material - Abmessungen'!E25)*'Material - Abmessungen'!E20*0.96 -> 5.5527871 | L15: mAh | M15: Kapazität nach der Formierung: | N15: 5.5726 | O15: mAh | P15: N:P-Verhältnis: | Q15: =((E15*1000-'Material - Abmessungen'!E17-('Material - Abmessungen'!E49*1000))*'Material - Abmessungen'!E10*0.697)/K15 -> 3.428439 | R15: Lithiierung der Anode: | S15: =Q15^(-1) -> 0.29167793
D17: Coulombsche Wirkungsgrade:
F18: 1. Zelle | G18: 2. Zelle | H18: 3. Zelle | I18: 4. Zelle | J18: 5. Zelle | K18: 6.Zelle
D19: 1. Laden (CC): | F19: 6.41254 | G19: 6.28729 | H19: 6.39454 | I19: 6.30121 | J19: 6.3471 | K19: 6.38706
D20: 2. Laden (CV): | F20: 0.09318 | G20: 0.09788 | H20: 0.09361 | I20: 0.09552 | J20: 0.094 | K20: 0.09589
D21: 1. Entladen (CC): | F21: 5.52882 | G21: 5.46751 | H21: 5.57418 | I21: 5.48871 | J21: 5.56261 | K21: 5.5743 | O21: Standardabweichung
D22: Coulombscher Wirkungsgrad: | F22: =F21/(F19+F20) -> 0.84983983 | G22: =G21/(G19+G20) -> 0.8562826 | H22: =H21/(H19+H20) -> 0.85913242 | I22: =I21/(I19+I20) -> 0.85804935 | J22: =J21/(J19+J20) -> 0.86361181 | K22: =K21/(K19+K20) -> 0.85984004 | L22: Durchschnittlicher ICE: | M22: =(F22+G22+H22+I22+J22+K22)/6 -> 0.85779268 | O22: =_xlfn.STDEV.S(F22,G22,H22,I22,J22,K22) -> 0.0045922279
D24: 3. Laden (CC): | F24: 5.49869 | G24: 5.43476 | H24: 5.54782 | I24: 5.46022 | J24: 5.53491 | K24: 5.54375
D25: 4. Laden (CV): | F25: 0.08408 | G25: 0.08496 | H25: 0.08217 | I25: 0.08291 | J25: 0.0818 | K25: 0.08409
D26: 2. Entladen (CC): | F26: 5.5206 | G26: 5.462 | H26: 5.57578 | I26: 5.48688 | J26: 5.57198 | K26: 5.57264 | O26: Standardabweichung
D27: Coulombscher Wirkungsgrad: | F27: =F26/(F24+F25) -> 0.98886395 | G27: =G26/(G24+G25) -> 0.98954295 | H27: =H26/(H24+H25) -> 0.99037121 | I27: =I26/(I24+I25) -> 0.9898523 | J27: =J26/(J24+J25) -> 0.99203626 | K27: =K26/(K24+K25) -> 0.99019162 | L27: Durchschnittlicher ICE: | M27: =(F27+G27+H27+I27+J27+K27)/6 -> 0.99014305 | O27: =_xlfn.STDEV.S(F27,G27,H27,I27,J27,K27) -> 0.0010695253

Sheet Vollzelle - 5µm - 35°C
B2: Prälithiierte Vollzellen (5µm) die den Einfluss einer erhöhten Prälithiierungstemepratur (35°C) während der Prälithiierungsdauer und der Formierung untersuchen
B5: Prälithiiert - 5µm - 48h Stunden - 35°C
B6: Atmosphäre während der Prälithiierung: | C6: O2: <2 ppm | D6: H2O: <2 ppm
C8: Atmosphäre während der Assemblierung: | G8: O2: <1,0 ppm | H8: O2: <1,0 ppm
B10: df_MH_MA_VZ_3,8_5µm_48h_35°C_1 | D10: 1. Anode: | E10: 0.0248 | F10: g | G10: 1. Kathode: | H10: 0.0372 | I10: g | J10: berechnete/theoretische Zellkapazität: | K10: =(H10*1000-'Material - Abmessungen'!E25)*'Material - Abmessungen'!E20*0.96 -> 5.4995071 | L10: mAh | M10: Kapazität nach der Formierung: | N10: 5.3414 | O10: mAh | P10: N:P-Verhältnis: | Q10: =((E10*1000-'Material - Abmessungen'!E17-('Material - Abmessungen'!E51*1000))*'Material - Abmessungen'!E10*0.697)/K10 -> 3.4942289 | R10: Lithiierung der Anode: | S10: =Q10^(-1) -> 0.28618617
B11: df_MH_MA_VZ_3,8_5µm_48h_35°C_2 | D11: 2. Anode: | E11: 0.0248 | F11: g | G11: 2. Kathode: | H11: 0.0378 | I11: g | J11: berechnete/theoretische Zellkapazität: | K11: =(H11*1000-'Material - Abmessungen'!E25)*'Material - Abmessungen'!E20*0.96 -> 5.6060671 | L11: mAh | M11: Kapazität nach der Formierung: | N11: 5.452 | O11: mAh | P11: N:P-Verhältnis: | Q11: =((E11*1000-'Material - Abmessungen'!E17-('Material - Abmessungen'!E51*1000))*'Material - Abmessungen'!E10*0.697)/K11 -> 3.4278107 | R11: Lithiierung der Anode: | S11: =Q11^(-1) -> 0.2917314
B12: df_MH_MA_VZ_3,8_5µm_48h_35°C_3 | D12: 3. Anode: | E12: 0.0249 | F12: g | G12: 3. Kathode: | H12: 0.0386 | I12: g | J12: berechnete/theoretische Zellkapazität: | K12: =(H12*1000-'Material - Abmessungen'!E25)*'Material - Abmessungen'!E20*0.96 -> 5.7481471 | L12: mAh | M12: Kapazität nach der Formierung: | N12: 5.452 | O12: mAh | P12: N:P-Verhältnis: | Q12: =((E12*1000-'Material - Abmessungen'!E17-('Material - Abmessungen'!E51*1000))*'Material - Abmessungen'!E10*0.697)/K12 -> 3.3864813 | R12: Lithiierung der Anode: | S12: =Q12^(-1) -> 0.29529175
B13: df_MH_MA_VZ_3,8_5µm_48h_35°C_4 | D13: 4. Anode: | E13: 0.0249 | F13: g | G13: 4. Kathode: | H13: 0.0383 | I13: g | J13: berechnete/theoretische Zellkapazität: | K13: =(H13*1000-'Material - Abmessungen'!E25)*'Material - Abmessungen'!E20*0.96 -> 5.6948671 | L13: mAh | M13: Kapazität nach der Formierung: | N13: 5.5056 | O13: mAh | P13: N:P-Verhältnis: | Q13: =((E13*1000-'Material - Abmessungen'!E17-('Material - Abmessungen'!E51*1000))*'Material - Abmessungen'!E10*0.697)/K13 -> 3.4181646 | R13: Lithiierung der Anode: | S13: =Q13^(-1) -> 0.29255467
B14: df_MH_MA_VZ_3,8_5µm_48h_35°C_5 | D14: 5. Anode: | E14: 0.0249 | F14: g | G14: 5.Kathode: | H14: 0.0379 | I14: g | J14: berechnete/theoretische Zellkapazität: | K14: =(H14*1000-'Material - Abmessungen'!E25)*'Material - Abmessungen'!E20*0.96 -> 5.6238271 | L14: mAh | M14: Kapazität nach der Formierung: | N14: 5.4171 | O14: mAh | P14: N:P-Verhältnis: | Q14: =((E14*1000-'Material - Abmessungen'!E17-('Material - Abmessungen'!E51*1000))*'Material - Abmessungen'!E10*0.697)/K14 -> 3.4613427 | R14: Lithiierung der Anode: | S14: =Q14^(-1) -> 0.28890523
B15: df_MH_MA_VZ_3,8_5µm_48h_35°C_6 | D15: 6. Anode: | E15: 0.025 | F15: g | G15: 6.Kathode: | H15: 0.0381 | I15: g | J15: berechnete/theoretische Zellkapazität: | K15: =(H15*1000-'Material - Abmessungen'!E25)*'Material - Abmessungen'!E20*0.96 -> 5.6593471 | L15: mAh | M15: Kapazität nach der Formierung: | N15: 5.4834 | O15: mAh | P15: N:P-Verhältnis: | Q15: =((E15*1000-'Material - Abmessungen'!E17-('Material - Abmessungen'!E51*1000))*'Material - Abmessungen'!E10*0.697)/K15 -> 3.4836968 | R15: Lithiierung der Anode: | S15: =Q15^(-1) -> 0.28705139
D17: Coulombsche Wirkungsgrade:
F18: 1. Zelle | G18: 2. Zelle | H18: 3. Zelle | I18: 4. Zelle | J18: 5. Zelle | K18: 6.Zelle
D19: 1. Laden (CC): | F19: 6.31042 | G19: 6.42757 | H19: 6.47261 | I19: 6.51522 | J19: 6.42795 | K19: 6.52325
D20: 2. Laden (CV): | F20: 0.09458 | G20: 0.09512 | H20: 0.09957 | I20: 0.09869 | J20: 0.09509 | K20: 0.09379
D21: 1. Entladen (CC): | F21: 5.38553 | G21: 5.49461 | H21: 5.50072 | I21: 5.55128 | J21: 5.46295 | K21: 5.53021 | O21: Standardabweichung
D22: Coulombscher Wirkungsgrad: | F22: =F21/(F19+F20) -> 0.84083216 | G22: =G21/(G19+G20) -> 0.84238405 | H22: =H21/(H19+H20) -> 0.83697038 | I22: =I21/(I19+I20) -> 0.83933407 | J22: =J21/(J19+J20) -> 0.83748528 | K22: =K21/(K19+K20) -> 0.83575284 | L22: Durchschnittlicher ICE: | M22: =(F22+G22+H22+I22+J22+K22)/6 -> 0.83879313 | O22: =_xlfn.STDEV.S(F22,G22,H22,I22,J22,K22) -> 0.002514803
D24: 3. Laden (CC): | F24: 5.35893 | G24: 5.4669 | H24: 5.47122 | I24: 5.52297 | J24: 5.43647 | K24: 5.50603
D25: 4. Laden (CV): | F25: 0.08099 | G25: 0.08238 | H25: 0.08249 | I25: 0.08321 | J25: 0.08164 | K25: 0.08048
D26: 2. Entladen (CC): | F26: 5.34137 | G26: 5.45199 | H26: 5.45196 | I26: 5.50558 | J26: 5.41711 | K26: 5.48335 | O26: Standardabweichung
D27: Coulombscher Wirkungsgrad: | F27: =F26/(F24+F25) -> 0.98188392 | G27: =G26/(G24+G25) -> 0.982468 | H27: =H26/(H24+H25) -> 0.98167891 | I27: =I26/(I24+I25) -> 0.98205552 | J27: =J26/(J24+J25) -> 0.98169663 | K27: =K26/(K24+K25) -> 0.98153409 | L27: Durchschnittlicher ICE: | M27: =(F27+G27+H27+I27+J27+K27)/6 -> 0.98188618 | O27: =_xlfn.STDEV.S(F27,G27,H27,I27,J27,K27) -> 0.00033765257

Sheet Material - Abmessungen
B2: Anodematerial (Si/G): | C2: CLM0001 | D2: Si: 69,7 % | E2: C: 19,9 % | F2: Super-C65: 2,0 % | G2: LiPAA: 8,2 % | H2: CMC: 0,2 %
B3: Kathodenmaterial (NAC): | C3: Excel TUM | D3: NCA-7051-b: 96% | E3: - | F3: Super-C65: 2,0 % | G3: PVDF: 2,0 %
B5: Spezifische Kapazität:
C6: Anode (Si/G):
D7: spezifische Flächenkapazität: | E7: 12.49 | F7: mAh/cm2
D8: Genutze Anodenkapazität: | E8: 3.8 | F8: mAh/cm2
D9: Genutze Lithiierungsgrad: | E9: =E8/E7*100 -> 30.424339 | F9: %
D10: spezifische Massenkapazität: | E10: 3.579 | F10: mAh/mg
D11: spezifische genutze Massenkapazität: | E11: =E10*(E9/100) -> 1.0888871 | F11: mAh/mg
D12: Dichte Kupferarbleiter: | E12: 8.96 | F12: g/cm3
D13: Durchmesser Anode: | E13: 15 | F13: mm
D14: Fläche Anode (CR2032): | E14: =((E13^2)/4)*3.1415/100 -> 1.7670938 | F14: cm2
D15: Theoretische Kapazität der Anode: | E15: =E8*E14 -> 6.7149563 | F15: mAh
D16: Dicke Kupferableiter: | E16: 10.5 | F16: µm
D17: Masse Kupferableiter: | E17: =(E16/10000)*E14*E12*1000 -> 16.624818 | F17: mg
C18: Kathode (NAC):
D19: spezifische Flächenkapazität: | E19: 3.8 | F19: mAh/cm2
D20: spezifische Massenkapazität: | E20: 0.185 | F20: mAh/mg
D21: Dichte Aluminiumableiter: | E21: 2.7 | F21: g/cm3
D22: Durchmesser Kathode | E22: 14 | F22: mm
D23: Fläche Kathode (CR2032): | E23: =((E22^2)/4)*3.1415/100 -> 1.539335 | F23: cm2
D24: Dicke Aluminiumableiter: | E24: 15 | F24: µm
D25: Masse Aluminiumableiter: | E25: =(E24/10000)*E23*E21*1000 -> 6.2343068 | F25: mg
C26: Kathode (NMC811) - Pouch:
D27: spezifische Flächenkapazität: | E27: 3.8 | F27: mAh/cm2
D28: spezifische Massenkapazität: | E28: 0.19 | F28: mAh/mg
D29: Dichte Aluminiumableiter: | E29: 2.7 | F29: g/cm3
D30: Dimensionen Kathode | E30: 30 x 30 | F30: mm
D31: Fläche Al-Kathode (Pouchzelle): | E31: =((30*30)-3*((3*3)-((3.1415*3^2)/4))+(13*10)+((3*3)-((3.1415*3^2)/4)))/100 -> 10.261367 | F31: cm2
D32: Dicke Aluminiumableiter: | E32: 12 | F32: µm
D33: Masse Aluminiumableiter: | E33: =(E32/10000)*E31*E29*1000 -> 33.246831 | F33: mg
C34: Anode (Si/G) - Pouch:
D35: spezifische Flächenkapazität: | E35: 12.49 | F35: mAh/cm2
D36: Genutze Anodenkapazität: | E36: 3.8 | F36: mAh/cm2
D37: Genutze Lithiierungsgrad: | E37: =E36/E35*100 -> 30.424339 | F37: %
D38: spezifische Massenkapazität: | E38: 3.579 | F38: mAh/mg
D39: spezifische genutze Massenkapazität: | E39: =E38*(E37/100) -> 1.0888871 | F39: mAh/mg
D40: Dichte Kupferarbleiter: | E40: 8.96 | F40: g/cm3
D41: Dimensionen Anode: | E41: 33 x 33 | F41: mm
D42: Fläche Anode: | E42: =((33*33)-3*((3*3)-((3.1415*3^2)/4))+(13*10)+((3*3)-((3.1415*3^2)/4)))/100 -> 12.151367 | F42: cm2
...

Sheet Spez. Kapazität
A1: Gruppe | B1: Zell-ID | C1: Geometrie | D1: Quellblatt | E1: Quellzeile | F1: Anodenmasse [g] | G1: Kathodenmasse gesamt [g] | H1: Al-Ableiter [mg] | I1: Aktivmaterialmasse [g] | J1: Kapazität nach Formierung [mAh] | K1: Spezifische Kapazität [mAh/g] | L1: Theoretische Zellkapazität [mAh]
A2: CR2032 10µm 1h | B2: df_MH_MA_VZ_3,8_10µm_1h_5 | C2: CR2032 | D2: Vollzelle - 10µm(Cr2032) - For | E2: 10 | F2: ='Vollzelle - 10µm(Cr2032) - For'!E10 -> 0.0249 | G2: ='Vollzelle - 10µm(Cr2032) - For'!H10 -> 0.0376 | H2: ='Material - Abmessungen'!$E$25 -> 6.2343068 | I2: =(G2-H2/1000)*0.96 -> 0.030111066 | J2: ='Vollzelle - 10µm(Cr2032) - For'!N10 -> 5.1619 | K2: =J2/I2 -> 171.42867 | L2: ='Vollzelle - 10µm(Cr2032) - For'!K10 -> 5.5705471
A3: CR2032 10µm 1h | B3: df_MH_MA_VZ_3,8_10µm_1h_6 | C3: CR2032 | D3: Vollzelle - 10µm(Cr2032) - For | E3: 11 | F3: ='Vollzelle - 10µm(Cr2032) - For'!E11 -> 0.0249 | G3: ='Vollzelle - 10µm(Cr2032) - For'!H11 -> 0.0368 | H3: ='Material - Abmessungen'!$E$25 -> 6.2343068 | I3: =(G3-H3/1000)*0.96 -> 0.029343066 | J3: ='Vollzelle - 10µm(Cr2032) - For'!N11 -> 4.9853 | K3: =J3/I3 -> 169.89704 | L3: ='Vollzelle - 10µm(Cr2032) - For'!K11 -> 5.4284671
A4: CR2032 10µm 1h | B4: df_MH_MA_VZ_3,8_10µm_1h_9 | C4: CR2032 | D4: Vollzelle - 10µm(Cr2032) - For | E4: 12 | F4: ='Vollzelle - 10µm(Cr2032) - For'!E12 -> 0.0252 | G4: ='Vollzelle - 10µm(Cr2032) - For'!H12 -> 0.0374 | H4: ='Material - Abmessungen'!$E$25 -> 6.2343068 | I4: =(G4-H4/1000)*0.96 -> 0.029919066 | J4: ='Vollzelle - 10µm(Cr2032) - For'!N12 -> 5.1486 | K4: =J4/I4 -> 172.08425 | L4: ='Vollzelle - 10µm(Cr2032) - For'!K12 -> 5.5350271
A5: CR2032 10µm 1h | B5: df_MH_MA_VZ_3,8_10µm_1h_10 | C5: CR2032 | D5: Vollzelle - 10µm(Cr2032) - For | E5: 13 | F5: ='Vollzelle - 10µm(Cr2032) - For'!E13 -> 0.0252 | G5: ='Vollzelle - 10µm(Cr2032) - For'!H13 -> 0.0374 | H5: ='Material - Abmessungen'!$E$25 -> 6.2343068 | I5: =(G5-H5/1000)*0.96 -> 0.029919066 | J5: ='Vollzelle - 10µm(Cr2032) - For'!N13 -> 5.1427 | K5: =J5/I5 -> 171.88705 | L5: ='Vollzelle - 10µm(Cr2032) - For'!K13 -> 5.5350271
A6: CR2032 10µm 1h | B6: df_MH_MA_VZ_3,8_10µm_1h_11 | C6: CR2032 | D6: Vollzelle - 10µm(Cr2032) - For | E6: 14 | F6: ='Vollzelle - 10µm(Cr2032) - For'!E14 -> 0.0252 | G6: ='Vollzelle - 10µm(Cr2032) - For'!H14 -> 0.037 | H6: ='Material - Abmessungen'!$E$25 -> 6.2343068 | I6: =(G6-H6/1000)*0.96 -> 0.029535066 | J6: ='Vollzelle - 10µm(Cr2032) - For'!N14 -> 5.0938 | K6: =J6/I6 -> 172.46618 | L6: ='Vollzelle - 10µm(Cr2032) - For'!K14 -> 5.4639871
A7: CR2032 10µm 1h | B7: df_MH_MA_VZ_3,8_10µm_1h_12 | C7: CR2032 | D7: Vollzelle - 10µm(Cr2032) - For | E7: 15 | F7: ='Vollzelle - 10µm(Cr2032) - For'!E15 -> 0.0251 | G7: ='Vollzelle - 10µm(Cr2032) - For'!H15 -> 0.0371 | H7: ='Material - Abmessungen'!$E$25 -> 6.2343068 | I7: =(G7-H7/1000)*0.96 -> 0.029631066 | J7: ='Vollzelle - 10µm(Cr2032) - For'!N15 -> 5.0602 | K7: =J7/I7 -> 170.77347 | L7: ='Vollzelle - 10µm(Cr2032) - For'!K15 -> 5.4817471
